<?xml version="1.0"?>
<robot name="crane">
<material name="black">
<color rgba="0.0 0.0 0.0 1.0" />
</material> 
<material name="white">
<color rgba="1.0 1.0 1.0 1.0" />
</material>


  <link name="base_link">
    <visual>
      <origin xyz="0 0 0.0227" rpy="0 0 0" />
      <geometry>
    <box size="0.0499 0.032 0.0454" />
      </geometry>
      <material name="white" />
 
    </visual>
  </link>
 
  <joint name="joint1" type="revolute">
    <parent link="base_link"/>
    <child link="link1"/>
    <origin xyz="0.0145 0 0.0227" rpy="0 0 0" />
    <axis xyz="0 0 1" />
    <limit lower="-2.61" upper="2.61" effort="0.5" velocity="6.0" />
  </joint>
 
  <link name="link1">

    <visual>
      <origin xyz="0 0 0" rpy="0 0 0" />
      <geometry>
        <box size="0.026 0.024 0.0575" />
      </geometry>
      <material name="black" />
    </visual>
      <collision>
        <origin xyz="0.0 0.0 0.0" rpy="0 0 0" />
        <geometry>
          <box size="0.026 0.024 0.0575"/>
        </geometry>
      </collision>
 


  </link>
 
  <joint name="joint2" type="revolute">
    <parent link="link1"/>
    <child link="link2"/>
    <origin xyz="0.024 0 0" rpy="0 0 0" />
    <axis xyz="1 0 0" />
    <limit lower="-1.75" upper="1.75" effort="0.5" velocity="6.0" />
  </joint>
 
  <link name="link2">
 
    <visual>
      <origin xyz="0.023 0 -0.03" rpy="0 0 0" />
      <geometry>
        <box size="0.0675 0.024 0.0675" />
      </geometry>
      <material name="white" />
    </visual>
      <collision>
        <origin xyz="0.023 0.0 -0.03" rpy="0 0 0" />
        <geometry>
          <box size="0.0675 0.024 0.0675"/>
        </geometry>
      </collision>

 
  </link>
 
  <joint name="joint3" type="revolute">
    <parent link="link2"/>
    <child link="link3"/>
    <origin xyz="0.0475 0 -0.0475" rpy="0 0 0" />
    <axis xyz="0 -1 0" />
    <limit lower="-2.55" upper="2.55" effort="0.5" velocity="6.0" />
  </joint>
 
  <link name="link3">
 
    <visual>
      <origin xyz="0.039 0 0" rpy="0 0 0" />
      <geometry>
        <box size="0.078 0.026 0.0475" />
      </geometry>
      <material name="black" />
    </visual>
       <collision>
        <origin xyz="0.039 0.0 0.0" rpy="0 0 0" />
        <geometry>
          <box size="0.078 0.026 0.0475"/>
        </geometry>
      </collision>

  </link>
 
  <joint name="joint4" type="revolute">
    <parent link="link3"/>
    <child link="link4"/>
    <origin xyz="0.078 0 -0.013" rpy="0 0 0" />
    <axis xyz="1 0 0" />
    <limit lower="-1.80" upper="1.80" effort="0.5" velocity="6.0" />
  </joint>
 
  <link name="link4">
    <visual>
      <origin xyz="0.012 0 0" rpy="0 0 0" />
      <geometry>
        <box size="0.024 0.024 0.024" />
      </geometry>
      <material name="white" />
    </visual>
      <collision>
        <origin xyz="0.012 0.0 0.0" rpy="0 0 0" />
        <geometry>
          <box size="0.024 0.024 0.024"/>
        </geometry>
      </collision>


   </link>
 
  <joint name="joint5" type="revolute">
    <parent link="link4"/>
    <child link="link5"/>
    <origin xyz="0.026 0 0" rpy="0 0 0" />
    <axis xyz="0 -1 0" />
    <limit lower="-0.69" upper="0.69" effort="0.5" velocity="6.0" />
  </joint>
 
  <link name="link5">
 
    <visual>
      <origin xyz="0.0235 0 0" rpy="0 0 0" />
      <geometry>
        <box size="0.05 0.026 0.024" />
      </geometry>
      <material name="white" />
    </visual>
      <collision>
        <origin xyz="0.0235 0.0 0.0" rpy="0 0 0" />
        <geometry>
          <box size="0.05 0.026 0.024"/>
        </geometry>
      </collision>
 
  </link>  


  <joint name="joint6" type="revolute">
    <parent link="link5"/>
    <child link="link6"/>
    <origin xyz="0.0375 0 0" rpy="0 0 0" />
    <axis xyz="1 0 0" />
    <limit lower="-0.69" upper="0.69" effort="0.5" velocity="6.0" />
  </joint>

  <link name="link6">
    <visual>
      <origin xyz="0.026 0 0" rpy="0 0 0" />
      <geometry>
        <box size="0.052 0.0475 0.026" />
      </geometry>
      <material name="black" />
    </visual>
      <collision>
        <origin xyz="0.026 0.0 0.0" rpy="0 0 0" />
        <geometry>
          <box size="0.052 0.0475 0.026"/>
        </geometry>
      </collision>


    <visual>
      <origin xyz="0.080 0.028 0.018" rpy="0 0 0" />
      <geometry>
        <box size="0.070 0.01 0.035" />
      </geometry>
      <material name="black" />
    </visual>

      <collision>
        <origin xyz="0.080 0.028 0.018" rpy="0 0 0" />
        <geometry>
          <box size="0.070 0.01 0.035"/>
        </geometry>
      </collision>
 

  </link>

  <joint name="joint7" type="revolute">
    <parent link="link6"/>
    <child link="link7"/>
    <origin xyz="0.052 -0.0187 0.0187" rpy="0 0 0" />
    <axis xyz="0 0 -1" />
    <limit lower="-0.69" upper="0.69" effort="0.5" velocity="6.0" />
  </joint>

  <link name="link7">

    <visual>
      <origin xyz="0.04 0 0" rpy="0 0 0" />
      <geometry>
        <box size="0.08 0.01 0.030" />
      </geometry>
      <material name="white" />
    </visual> 

      <collision>
        <origin xyz="0.04 0.0 0.0" rpy="0 0 0" />
        <geometry>
          <box size="0.08 0.01 0.03"/>
        </geometry>
      </collision>

 
  </link>
 
</robot>



